2022-04-28 14:04:13,381 [ERROR] app: Exception on /register [POST]
Traceback (most recent call last):
  File "/usr/local/lib/python3.8/site-packages/sqlalchemy/engine/base.py", line 1819, in _execute_context
    self.dialect.do_execute(
  File "/usr/local/lib/python3.8/site-packages/sqlalchemy/engine/default.py", line 732, in do_execute
    cursor.execute(statement, parameters)
sqlite3.OperationalError: no such table: users

The above exception was the direct cause of the following exception:

Traceback (most recent call last):
  File "/usr/local/lib/python3.8/site-packages/flask/app.py", line 2077, in wsgi_app
    response = self.full_dispatch_request()
  File "/usr/local/lib/python3.8/site-packages/flask/app.py", line 1525, in full_dispatch_request
    rv = self.handle_user_exception(e)
  File "/usr/local/lib/python3.8/site-packages/flask/app.py", line 1523, in full_dispatch_request
    rv = self.dispatch_request()
  File "/usr/local/lib/python3.8/site-packages/flask/app.py", line 1509, in dispatch_request
    return self.ensure_sync(self.view_functions[rule.endpoint])(**req.view_args)
  File "/home/myuser/app/auth/__init__.py", line 19, in register
    user = User.query.filter_by(email=form.email.data).first()
  File "/usr/local/lib/python3.8/site-packages/sqlalchemy/orm/query.py", line 2819, in first
    return self.limit(1)._iter().first()
  File "/usr/local/lib/python3.8/site-packages/sqlalchemy/orm/query.py", line 2903, in _iter
    result = self.session.execute(
  File "/usr/local/lib/python3.8/site-packages/sqlalchemy/orm/session.py", line 1692, in execute
    result = conn._execute_20(statement, params or {}, execution_options)
  File "/usr/local/lib/python3.8/site-packages/sqlalchemy/engine/base.py", line 1631, in _execute_20
    return meth(self, args_10style, kwargs_10style, execution_options)
  File "/usr/local/lib/python3.8/site-packages/sqlalchemy/sql/elements.py", line 326, in _execute_on_connection
    return connection._execute_clauseelement(
  File "/usr/local/lib/python3.8/site-packages/sqlalchemy/engine/base.py", line 1498, in _execute_clauseelement
    ret = self._execute_context(
  File "/usr/local/lib/python3.8/site-packages/sqlalchemy/engine/base.py", line 1862, in _execute_context
    self._handle_dbapi_exception(
  File "/usr/local/lib/python3.8/site-packages/sqlalchemy/engine/base.py", line 2043, in _handle_dbapi_exception
    util.raise_(
  File "/usr/local/lib/python3.8/site-packages/sqlalchemy/util/compat.py", line 207, in raise_
    raise exception
  File "/usr/local/lib/python3.8/site-packages/sqlalchemy/engine/base.py", line 1819, in _execute_context
    self.dialect.do_execute(
  File "/usr/local/lib/python3.8/site-packages/sqlalchemy/engine/default.py", line 732, in do_execute
    cursor.execute(statement, parameters)
sqlalchemy.exc.OperationalError: (sqlite3.OperationalError) no such table: users
[SQL: SELECT users.is_active AS users_is_active, users.id AS users_id, users.email AS users_email, users.password AS users_password, users.about AS users_about, users.authenticated AS users_authenticated, users.registered_on AS users_registered_on, users.is_admin AS users_is_admin 
FROM users 
WHERE users.email = ?
 LIMIT ? OFFSET ?]
[parameters: ('bob@gmail.com', 1, 0)]
(Background on this error at: https://sqlalche.me/e/14/e3q8)
2022-04-28 14:22:54,938 [ERROR] app: Exception on /login [POST]
Traceback (most recent call last):
  File "/usr/local/lib/python3.8/site-packages/sqlalchemy/engine/base.py", line 1819, in _execute_context
    self.dialect.do_execute(
  File "/usr/local/lib/python3.8/site-packages/sqlalchemy/engine/default.py", line 732, in do_execute
    cursor.execute(statement, parameters)
sqlite3.OperationalError: no such table: users

The above exception was the direct cause of the following exception:

Traceback (most recent call last):
  File "/usr/local/lib/python3.8/site-packages/flask/app.py", line 2077, in wsgi_app
    response = self.full_dispatch_request()
  File "/usr/local/lib/python3.8/site-packages/flask/app.py", line 1525, in full_dispatch_request
    rv = self.handle_user_exception(e)
  File "/usr/local/lib/python3.8/site-packages/flask/app.py", line 1523, in full_dispatch_request
    rv = self.dispatch_request()
  File "/usr/local/lib/python3.8/site-packages/flask/app.py", line 1509, in dispatch_request
    return self.ensure_sync(self.view_functions[rule.endpoint])(**req.view_args)
  File "/home/myuser/app/auth/__init__.py", line 41, in login
    user = User.query.filter_by(email=form.email.data).first()
  File "/usr/local/lib/python3.8/site-packages/sqlalchemy/orm/query.py", line 2819, in first
    return self.limit(1)._iter().first()
  File "/usr/local/lib/python3.8/site-packages/sqlalchemy/orm/query.py", line 2903, in _iter
    result = self.session.execute(
  File "/usr/local/lib/python3.8/site-packages/sqlalchemy/orm/session.py", line 1692, in execute
    result = conn._execute_20(statement, params or {}, execution_options)
  File "/usr/local/lib/python3.8/site-packages/sqlalchemy/engine/base.py", line 1631, in _execute_20
    return meth(self, args_10style, kwargs_10style, execution_options)
  File "/usr/local/lib/python3.8/site-packages/sqlalchemy/sql/elements.py", line 326, in _execute_on_connection
    return connection._execute_clauseelement(
  File "/usr/local/lib/python3.8/site-packages/sqlalchemy/engine/base.py", line 1498, in _execute_clauseelement
    ret = self._execute_context(
  File "/usr/local/lib/python3.8/site-packages/sqlalchemy/engine/base.py", line 1862, in _execute_context
    self._handle_dbapi_exception(
  File "/usr/local/lib/python3.8/site-packages/sqlalchemy/engine/base.py", line 2043, in _handle_dbapi_exception
    util.raise_(
  File "/usr/local/lib/python3.8/site-packages/sqlalchemy/util/compat.py", line 207, in raise_
    raise exception
  File "/usr/local/lib/python3.8/site-packages/sqlalchemy/engine/base.py", line 1819, in _execute_context
    self.dialect.do_execute(
  File "/usr/local/lib/python3.8/site-packages/sqlalchemy/engine/default.py", line 732, in do_execute
    cursor.execute(statement, parameters)
sqlalchemy.exc.OperationalError: (sqlite3.OperationalError) no such table: users
[SQL: SELECT users.is_active AS users_is_active, users.id AS users_id, users.email AS users_email, users.password AS users_password, users.about AS users_about, users.authenticated AS users_authenticated, users.registered_on AS users_registered_on, users.is_admin AS users_is_admin 
FROM users 
WHERE users.email = ?
 LIMIT ? OFFSET ?]
[parameters: ('bob@gmail.com', 1, 0)]
(Background on this error at: https://sqlalche.me/e/14/e3q8)
2022-04-28 14:23:10,286 [ERROR] app: Exception on /register [POST]
Traceback (most recent call last):
  File "/usr/local/lib/python3.8/site-packages/sqlalchemy/engine/base.py", line 1819, in _execute_context
    self.dialect.do_execute(
  File "/usr/local/lib/python3.8/site-packages/sqlalchemy/engine/default.py", line 732, in do_execute
    cursor.execute(statement, parameters)
sqlite3.OperationalError: no such table: users

The above exception was the direct cause of the following exception:

Traceback (most recent call last):
  File "/usr/local/lib/python3.8/site-packages/flask/app.py", line 2077, in wsgi_app
    response = self.full_dispatch_request()
  File "/usr/local/lib/python3.8/site-packages/flask/app.py", line 1525, in full_dispatch_request
    rv = self.handle_user_exception(e)
  File "/usr/local/lib/python3.8/site-packages/flask/app.py", line 1523, in full_dispatch_request
    rv = self.dispatch_request()
  File "/usr/local/lib/python3.8/site-packages/flask/app.py", line 1509, in dispatch_request
    return self.ensure_sync(self.view_functions[rule.endpoint])(**req.view_args)
  File "/home/myuser/app/auth/__init__.py", line 19, in register
    user = User.query.filter_by(email=form.email.data).first()
  File "/usr/local/lib/python3.8/site-packages/sqlalchemy/orm/query.py", line 2819, in first
    return self.limit(1)._iter().first()
  File "/usr/local/lib/python3.8/site-packages/sqlalchemy/orm/query.py", line 2903, in _iter
    result = self.session.execute(
  File "/usr/local/lib/python3.8/site-packages/sqlalchemy/orm/session.py", line 1692, in execute
    result = conn._execute_20(statement, params or {}, execution_options)
  File "/usr/local/lib/python3.8/site-packages/sqlalchemy/engine/base.py", line 1631, in _execute_20
    return meth(self, args_10style, kwargs_10style, execution_options)
  File "/usr/local/lib/python3.8/site-packages/sqlalchemy/sql/elements.py", line 326, in _execute_on_connection
    return connection._execute_clauseelement(
  File "/usr/local/lib/python3.8/site-packages/sqlalchemy/engine/base.py", line 1498, in _execute_clauseelement
    ret = self._execute_context(
  File "/usr/local/lib/python3.8/site-packages/sqlalchemy/engine/base.py", line 1862, in _execute_context
    self._handle_dbapi_exception(
  File "/usr/local/lib/python3.8/site-packages/sqlalchemy/engine/base.py", line 2043, in _handle_dbapi_exception
    util.raise_(
  File "/usr/local/lib/python3.8/site-packages/sqlalchemy/util/compat.py", line 207, in raise_
    raise exception
  File "/usr/local/lib/python3.8/site-packages/sqlalchemy/engine/base.py", line 1819, in _execute_context
    self.dialect.do_execute(
  File "/usr/local/lib/python3.8/site-packages/sqlalchemy/engine/default.py", line 732, in do_execute
    cursor.execute(statement, parameters)
sqlalchemy.exc.OperationalError: (sqlite3.OperationalError) no such table: users
[SQL: SELECT users.is_active AS users_is_active, users.id AS users_id, users.email AS users_email, users.password AS users_password, users.about AS users_about, users.authenticated AS users_authenticated, users.registered_on AS users_registered_on, users.is_admin AS users_is_admin 
FROM users 
WHERE users.email = ?
 LIMIT ? OFFSET ?]
[parameters: ('bob@gmail.com', 1, 0)]
(Background on this error at: https://sqlalche.me/e/14/e3q8)
2022-04-28 14:25:51,440 [ERROR] app: Exception on /register [POST]
Traceback (most recent call last):
  File "/usr/local/lib/python3.8/site-packages/sqlalchemy/engine/base.py", line 1819, in _execute_context
    self.dialect.do_execute(
  File "/usr/local/lib/python3.8/site-packages/sqlalchemy/engine/default.py", line 732, in do_execute
    cursor.execute(statement, parameters)
sqlite3.OperationalError: no such table: users

The above exception was the direct cause of the following exception:

Traceback (most recent call last):
  File "/usr/local/lib/python3.8/site-packages/flask/app.py", line 2077, in wsgi_app
    response = self.full_dispatch_request()
  File "/usr/local/lib/python3.8/site-packages/flask/app.py", line 1525, in full_dispatch_request
    rv = self.handle_user_exception(e)
  File "/usr/local/lib/python3.8/site-packages/flask/app.py", line 1523, in full_dispatch_request
    rv = self.dispatch_request()
  File "/usr/local/lib/python3.8/site-packages/flask/app.py", line 1509, in dispatch_request
    return self.ensure_sync(self.view_functions[rule.endpoint])(**req.view_args)
  File "/home/myuser/app/auth/__init__.py", line 19, in register
    user = User.query.filter_by(email=form.email.data).first()
  File "/usr/local/lib/python3.8/site-packages/sqlalchemy/orm/query.py", line 2819, in first
    return self.limit(1)._iter().first()
  File "/usr/local/lib/python3.8/site-packages/sqlalchemy/orm/query.py", line 2903, in _iter
    result = self.session.execute(
  File "/usr/local/lib/python3.8/site-packages/sqlalchemy/orm/session.py", line 1692, in execute
    result = conn._execute_20(statement, params or {}, execution_options)
  File "/usr/local/lib/python3.8/site-packages/sqlalchemy/engine/base.py", line 1631, in _execute_20
    return meth(self, args_10style, kwargs_10style, execution_options)
  File "/usr/local/lib/python3.8/site-packages/sqlalchemy/sql/elements.py", line 326, in _execute_on_connection
    return connection._execute_clauseelement(
  File "/usr/local/lib/python3.8/site-packages/sqlalchemy/engine/base.py", line 1498, in _execute_clauseelement
    ret = self._execute_context(
  File "/usr/local/lib/python3.8/site-packages/sqlalchemy/engine/base.py", line 1862, in _execute_context
    self._handle_dbapi_exception(
  File "/usr/local/lib/python3.8/site-packages/sqlalchemy/engine/base.py", line 2043, in _handle_dbapi_exception
    util.raise_(
  File "/usr/local/lib/python3.8/site-packages/sqlalchemy/util/compat.py", line 207, in raise_
    raise exception
  File "/usr/local/lib/python3.8/site-packages/sqlalchemy/engine/base.py", line 1819, in _execute_context
    self.dialect.do_execute(
  File "/usr/local/lib/python3.8/site-packages/sqlalchemy/engine/default.py", line 732, in do_execute
    cursor.execute(statement, parameters)
sqlalchemy.exc.OperationalError: (sqlite3.OperationalError) no such table: users
[SQL: SELECT users.is_active AS users_is_active, users.id AS users_id, users.email AS users_email, users.password AS users_password, users.about AS users_about, users.authenticated AS users_authenticated, users.registered_on AS users_registered_on, users.is_admin AS users_is_admin 
FROM users 
WHERE users.email = ?
 LIMIT ? OFFSET ?]
[parameters: ('bob@gmail.com', 1, 0)]
(Background on this error at: https://sqlalche.me/e/14/e3q8)
2022-04-28 14:46:45,099 [ERROR] app: Exception on /register [POST]
Traceback (most recent call last):
  File "/usr/local/lib/python3.8/site-packages/sqlalchemy/engine/base.py", line 1819, in _execute_context
    self.dialect.do_execute(
  File "/usr/local/lib/python3.8/site-packages/sqlalchemy/engine/default.py", line 732, in do_execute
    cursor.execute(statement, parameters)
sqlite3.OperationalError: no such table: users

The above exception was the direct cause of the following exception:

Traceback (most recent call last):
  File "/usr/local/lib/python3.8/site-packages/flask/app.py", line 2077, in wsgi_app
    response = self.full_dispatch_request()
  File "/usr/local/lib/python3.8/site-packages/flask/app.py", line 1525, in full_dispatch_request
    rv = self.handle_user_exception(e)
  File "/usr/local/lib/python3.8/site-packages/flask/app.py", line 1523, in full_dispatch_request
    rv = self.dispatch_request()
  File "/usr/local/lib/python3.8/site-packages/flask/app.py", line 1509, in dispatch_request
    return self.ensure_sync(self.view_functions[rule.endpoint])(**req.view_args)
  File "/home/myuser/app/auth/__init__.py", line 19, in register
    user = User.query.filter_by(email=form.email.data).first()
  File "/usr/local/lib/python3.8/site-packages/sqlalchemy/orm/query.py", line 2819, in first
    return self.limit(1)._iter().first()
  File "/usr/local/lib/python3.8/site-packages/sqlalchemy/orm/query.py", line 2903, in _iter
    result = self.session.execute(
  File "/usr/local/lib/python3.8/site-packages/sqlalchemy/orm/session.py", line 1692, in execute
    result = conn._execute_20(statement, params or {}, execution_options)
  File "/usr/local/lib/python3.8/site-packages/sqlalchemy/engine/base.py", line 1631, in _execute_20
    return meth(self, args_10style, kwargs_10style, execution_options)
  File "/usr/local/lib/python3.8/site-packages/sqlalchemy/sql/elements.py", line 326, in _execute_on_connection
    return connection._execute_clauseelement(
  File "/usr/local/lib/python3.8/site-packages/sqlalchemy/engine/base.py", line 1498, in _execute_clauseelement
    ret = self._execute_context(
  File "/usr/local/lib/python3.8/site-packages/sqlalchemy/engine/base.py", line 1862, in _execute_context
    self._handle_dbapi_exception(
  File "/usr/local/lib/python3.8/site-packages/sqlalchemy/engine/base.py", line 2043, in _handle_dbapi_exception
    util.raise_(
  File "/usr/local/lib/python3.8/site-packages/sqlalchemy/util/compat.py", line 207, in raise_
    raise exception
  File "/usr/local/lib/python3.8/site-packages/sqlalchemy/engine/base.py", line 1819, in _execute_context
    self.dialect.do_execute(
  File "/usr/local/lib/python3.8/site-packages/sqlalchemy/engine/default.py", line 732, in do_execute
    cursor.execute(statement, parameters)
sqlalchemy.exc.OperationalError: (sqlite3.OperationalError) no such table: users
[SQL: SELECT users.is_active AS users_is_active, users.id AS users_id, users.email AS users_email, users.password AS users_password, users.about AS users_about, users.authenticated AS users_authenticated, users.registered_on AS users_registered_on, users.is_admin AS users_is_admin 
FROM users 
WHERE users.email = ?
 LIMIT ? OFFSET ?]
[parameters: ('bob2@gmail.com', 1, 0)]
(Background on this error at: https://sqlalche.me/e/14/e3q8)
2022-04-28 14:52:41,787 [ERROR] app: Exception on /register [POST]
Traceback (most recent call last):
  File "/usr/local/lib/python3.8/site-packages/sqlalchemy/engine/base.py", line 1819, in _execute_context
    self.dialect.do_execute(
  File "/usr/local/lib/python3.8/site-packages/sqlalchemy/engine/default.py", line 732, in do_execute
    cursor.execute(statement, parameters)
sqlite3.OperationalError: no such table: users

The above exception was the direct cause of the following exception:

Traceback (most recent call last):
  File "/usr/local/lib/python3.8/site-packages/flask/app.py", line 2077, in wsgi_app
    response = self.full_dispatch_request()
  File "/usr/local/lib/python3.8/site-packages/flask/app.py", line 1525, in full_dispatch_request
    rv = self.handle_user_exception(e)
  File "/usr/local/lib/python3.8/site-packages/flask/app.py", line 1523, in full_dispatch_request
    rv = self.dispatch_request()
  File "/usr/local/lib/python3.8/site-packages/flask/app.py", line 1509, in dispatch_request
    return self.ensure_sync(self.view_functions[rule.endpoint])(**req.view_args)
  File "/home/myuser/app/auth/__init__.py", line 19, in register
    user = User.query.filter_by(email=form.email.data).first()
  File "/usr/local/lib/python3.8/site-packages/sqlalchemy/orm/query.py", line 2819, in first
    return self.limit(1)._iter().first()
  File "/usr/local/lib/python3.8/site-packages/sqlalchemy/orm/query.py", line 2903, in _iter
    result = self.session.execute(
  File "/usr/local/lib/python3.8/site-packages/sqlalchemy/orm/session.py", line 1692, in execute
    result = conn._execute_20(statement, params or {}, execution_options)
  File "/usr/local/lib/python3.8/site-packages/sqlalchemy/engine/base.py", line 1631, in _execute_20
    return meth(self, args_10style, kwargs_10style, execution_options)
  File "/usr/local/lib/python3.8/site-packages/sqlalchemy/sql/elements.py", line 326, in _execute_on_connection
    return connection._execute_clauseelement(
  File "/usr/local/lib/python3.8/site-packages/sqlalchemy/engine/base.py", line 1498, in _execute_clauseelement
    ret = self._execute_context(
  File "/usr/local/lib/python3.8/site-packages/sqlalchemy/engine/base.py", line 1862, in _execute_context
    self._handle_dbapi_exception(
  File "/usr/local/lib/python3.8/site-packages/sqlalchemy/engine/base.py", line 2043, in _handle_dbapi_exception
    util.raise_(
  File "/usr/local/lib/python3.8/site-packages/sqlalchemy/util/compat.py", line 207, in raise_
    raise exception
  File "/usr/local/lib/python3.8/site-packages/sqlalchemy/engine/base.py", line 1819, in _execute_context
    self.dialect.do_execute(
  File "/usr/local/lib/python3.8/site-packages/sqlalchemy/engine/default.py", line 732, in do_execute
    cursor.execute(statement, parameters)
sqlalchemy.exc.OperationalError: (sqlite3.OperationalError) no such table: users
[SQL: SELECT users.is_active AS users_is_active, users.id AS users_id, users.email AS users_email, users.password AS users_password, users.about AS users_about, users.authenticated AS users_authenticated, users.registered_on AS users_registered_on, users.is_admin AS users_is_admin 
FROM users 
WHERE users.email = ?
 LIMIT ? OFFSET ?]
[parameters: ('bob2@gmail.com', 1, 0)]
(Background on this error at: https://sqlalche.me/e/14/e3q8)
2022-04-28 14:55:09,247 [ERROR] app: Exception on /register [POST]
Traceback (most recent call last):
  File "/usr/local/lib/python3.8/site-packages/sqlalchemy/engine/base.py", line 1819, in _execute_context
    self.dialect.do_execute(
  File "/usr/local/lib/python3.8/site-packages/sqlalchemy/engine/default.py", line 732, in do_execute
    cursor.execute(statement, parameters)
sqlite3.OperationalError: no such table: users

The above exception was the direct cause of the following exception:

Traceback (most recent call last):
  File "/usr/local/lib/python3.8/site-packages/flask/app.py", line 2077, in wsgi_app
    response = self.full_dispatch_request()
  File "/usr/local/lib/python3.8/site-packages/flask/app.py", line 1525, in full_dispatch_request
    rv = self.handle_user_exception(e)
  File "/usr/local/lib/python3.8/site-packages/flask/app.py", line 1523, in full_dispatch_request
    rv = self.dispatch_request()
  File "/usr/local/lib/python3.8/site-packages/flask/app.py", line 1509, in dispatch_request
    return self.ensure_sync(self.view_functions[rule.endpoint])(**req.view_args)
  File "/home/myuser/app/auth/__init__.py", line 19, in register
    user = User.query.filter_by(email=form.email.data).first()
  File "/usr/local/lib/python3.8/site-packages/sqlalchemy/orm/query.py", line 2819, in first
    return self.limit(1)._iter().first()
  File "/usr/local/lib/python3.8/site-packages/sqlalchemy/orm/query.py", line 2903, in _iter
    result = self.session.execute(
  File "/usr/local/lib/python3.8/site-packages/sqlalchemy/orm/session.py", line 1692, in execute
    result = conn._execute_20(statement, params or {}, execution_options)
  File "/usr/local/lib/python3.8/site-packages/sqlalchemy/engine/base.py", line 1631, in _execute_20
    return meth(self, args_10style, kwargs_10style, execution_options)
  File "/usr/local/lib/python3.8/site-packages/sqlalchemy/sql/elements.py", line 326, in _execute_on_connection
    return connection._execute_clauseelement(
  File "/usr/local/lib/python3.8/site-packages/sqlalchemy/engine/base.py", line 1498, in _execute_clauseelement
    ret = self._execute_context(
  File "/usr/local/lib/python3.8/site-packages/sqlalchemy/engine/base.py", line 1862, in _execute_context
    self._handle_dbapi_exception(
  File "/usr/local/lib/python3.8/site-packages/sqlalchemy/engine/base.py", line 2043, in _handle_dbapi_exception
    util.raise_(
  File "/usr/local/lib/python3.8/site-packages/sqlalchemy/util/compat.py", line 207, in raise_
    raise exception
  File "/usr/local/lib/python3.8/site-packages/sqlalchemy/engine/base.py", line 1819, in _execute_context
    self.dialect.do_execute(
  File "/usr/local/lib/python3.8/site-packages/sqlalchemy/engine/default.py", line 732, in do_execute
    cursor.execute(statement, parameters)
sqlalchemy.exc.OperationalError: (sqlite3.OperationalError) no such table: users
[SQL: SELECT users.is_active AS users_is_active, users.id AS users_id, users.email AS users_email, users.password AS users_password, users.about AS users_about, users.authenticated AS users_authenticated, users.registered_on AS users_registered_on, users.is_admin AS users_is_admin 
FROM users 
WHERE users.email = ?
 LIMIT ? OFFSET ?]
[parameters: ('bob2@gmail.com', 1, 0)]
(Background on this error at: https://sqlalche.me/e/14/e3q8)
2022-04-28 14:56:48,918 [ERROR] app: Exception on /register [POST]
Traceback (most recent call last):
  File "/usr/local/lib/python3.8/site-packages/sqlalchemy/engine/base.py", line 1819, in _execute_context
    self.dialect.do_execute(
  File "/usr/local/lib/python3.8/site-packages/sqlalchemy/engine/default.py", line 732, in do_execute
    cursor.execute(statement, parameters)
sqlite3.OperationalError: no such table: users

The above exception was the direct cause of the following exception:

Traceback (most recent call last):
  File "/usr/local/lib/python3.8/site-packages/flask/app.py", line 2077, in wsgi_app
    response = self.full_dispatch_request()
  File "/usr/local/lib/python3.8/site-packages/flask/app.py", line 1525, in full_dispatch_request
    rv = self.handle_user_exception(e)
  File "/usr/local/lib/python3.8/site-packages/flask/app.py", line 1523, in full_dispatch_request
    rv = self.dispatch_request()
  File "/usr/local/lib/python3.8/site-packages/flask/app.py", line 1509, in dispatch_request
    return self.ensure_sync(self.view_functions[rule.endpoint])(**req.view_args)
  File "/home/myuser/app/auth/__init__.py", line 19, in register
    user = User.query.filter_by(email=form.email.data).first()
  File "/usr/local/lib/python3.8/site-packages/sqlalchemy/orm/query.py", line 2819, in first
    return self.limit(1)._iter().first()
  File "/usr/local/lib/python3.8/site-packages/sqlalchemy/orm/query.py", line 2903, in _iter
    result = self.session.execute(
  File "/usr/local/lib/python3.8/site-packages/sqlalchemy/orm/session.py", line 1692, in execute
    result = conn._execute_20(statement, params or {}, execution_options)
  File "/usr/local/lib/python3.8/site-packages/sqlalchemy/engine/base.py", line 1631, in _execute_20
    return meth(self, args_10style, kwargs_10style, execution_options)
  File "/usr/local/lib/python3.8/site-packages/sqlalchemy/sql/elements.py", line 326, in _execute_on_connection
    return connection._execute_clauseelement(
  File "/usr/local/lib/python3.8/site-packages/sqlalchemy/engine/base.py", line 1498, in _execute_clauseelement
    ret = self._execute_context(
  File "/usr/local/lib/python3.8/site-packages/sqlalchemy/engine/base.py", line 1862, in _execute_context
    self._handle_dbapi_exception(
  File "/usr/local/lib/python3.8/site-packages/sqlalchemy/engine/base.py", line 2043, in _handle_dbapi_exception
    util.raise_(
  File "/usr/local/lib/python3.8/site-packages/sqlalchemy/util/compat.py", line 207, in raise_
    raise exception
  File "/usr/local/lib/python3.8/site-packages/sqlalchemy/engine/base.py", line 1819, in _execute_context
    self.dialect.do_execute(
  File "/usr/local/lib/python3.8/site-packages/sqlalchemy/engine/default.py", line 732, in do_execute
    cursor.execute(statement, parameters)
sqlalchemy.exc.OperationalError: (sqlite3.OperationalError) no such table: users
[SQL: SELECT users.is_active AS users_is_active, users.id AS users_id, users.email AS users_email, users.password AS users_password, users.about AS users_about, users.authenticated AS users_authenticated, users.registered_on AS users_registered_on, users.is_admin AS users_is_admin 
FROM users 
WHERE users.email = ?
 LIMIT ? OFFSET ?]
[parameters: ('bob2@gmail.com', 1, 0)]
(Background on this error at: https://sqlalche.me/e/14/e3q8)
2022-04-28 14:58:48,362 [ERROR] app: Exception on /register [POST]
Traceback (most recent call last):
  File "/usr/local/lib/python3.8/site-packages/sqlalchemy/engine/base.py", line 1819, in _execute_context
    self.dialect.do_execute(
  File "/usr/local/lib/python3.8/site-packages/sqlalchemy/engine/default.py", line 732, in do_execute
    cursor.execute(statement, parameters)
sqlite3.OperationalError: no such table: users

The above exception was the direct cause of the following exception:

Traceback (most recent call last):
  File "/usr/local/lib/python3.8/site-packages/flask/app.py", line 2077, in wsgi_app
    response = self.full_dispatch_request()
  File "/usr/local/lib/python3.8/site-packages/flask/app.py", line 1525, in full_dispatch_request
    rv = self.handle_user_exception(e)
  File "/usr/local/lib/python3.8/site-packages/flask/app.py", line 1523, in full_dispatch_request
    rv = self.dispatch_request()
  File "/usr/local/lib/python3.8/site-packages/flask/app.py", line 1509, in dispatch_request
    return self.ensure_sync(self.view_functions[rule.endpoint])(**req.view_args)
  File "/home/myuser/app/auth/__init__.py", line 19, in register
    user = User.query.filter_by(email=form.email.data).first()
  File "/usr/local/lib/python3.8/site-packages/sqlalchemy/orm/query.py", line 2819, in first
    return self.limit(1)._iter().first()
  File "/usr/local/lib/python3.8/site-packages/sqlalchemy/orm/query.py", line 2903, in _iter
    result = self.session.execute(
  File "/usr/local/lib/python3.8/site-packages/sqlalchemy/orm/session.py", line 1692, in execute
    result = conn._execute_20(statement, params or {}, execution_options)
  File "/usr/local/lib/python3.8/site-packages/sqlalchemy/engine/base.py", line 1631, in _execute_20
    return meth(self, args_10style, kwargs_10style, execution_options)
  File "/usr/local/lib/python3.8/site-packages/sqlalchemy/sql/elements.py", line 326, in _execute_on_connection
    return connection._execute_clauseelement(
  File "/usr/local/lib/python3.8/site-packages/sqlalchemy/engine/base.py", line 1498, in _execute_clauseelement
    ret = self._execute_context(
  File "/usr/local/lib/python3.8/site-packages/sqlalchemy/engine/base.py", line 1862, in _execute_context
    self._handle_dbapi_exception(
  File "/usr/local/lib/python3.8/site-packages/sqlalchemy/engine/base.py", line 2043, in _handle_dbapi_exception
    util.raise_(
  File "/usr/local/lib/python3.8/site-packages/sqlalchemy/util/compat.py", line 207, in raise_
    raise exception
  File "/usr/local/lib/python3.8/site-packages/sqlalchemy/engine/base.py", line 1819, in _execute_context
    self.dialect.do_execute(
  File "/usr/local/lib/python3.8/site-packages/sqlalchemy/engine/default.py", line 732, in do_execute
    cursor.execute(statement, parameters)
sqlalchemy.exc.OperationalError: (sqlite3.OperationalError) no such table: users
[SQL: SELECT users.is_active AS users_is_active, users.id AS users_id, users.email AS users_email, users.password AS users_password, users.about AS users_about, users.authenticated AS users_authenticated, users.registered_on AS users_registered_on, users.is_admin AS users_is_admin 
FROM users 
WHERE users.email = ?
 LIMIT ? OFFSET ?]
[parameters: ('bob3@gmail.com', 1, 0)]
(Background on this error at: https://sqlalche.me/e/14/e3q8)
2022-04-28 14:59:31,867 [ERROR] app: Exception on /login [POST]
Traceback (most recent call last):
  File "/usr/local/lib/python3.8/site-packages/sqlalchemy/engine/base.py", line 1819, in _execute_context
    self.dialect.do_execute(
  File "/usr/local/lib/python3.8/site-packages/sqlalchemy/engine/default.py", line 732, in do_execute
    cursor.execute(statement, parameters)
sqlite3.OperationalError: no such table: users

The above exception was the direct cause of the following exception:

Traceback (most recent call last):
  File "/usr/local/lib/python3.8/site-packages/flask/app.py", line 2077, in wsgi_app
    response = self.full_dispatch_request()
  File "/usr/local/lib/python3.8/site-packages/flask/app.py", line 1525, in full_dispatch_request
    rv = self.handle_user_exception(e)
  File "/usr/local/lib/python3.8/site-packages/flask/app.py", line 1523, in full_dispatch_request
    rv = self.dispatch_request()
  File "/usr/local/lib/python3.8/site-packages/flask/app.py", line 1509, in dispatch_request
    return self.ensure_sync(self.view_functions[rule.endpoint])(**req.view_args)
  File "/home/myuser/app/auth/__init__.py", line 41, in login
    user = User.query.filter_by(email=form.email.data).first()
  File "/usr/local/lib/python3.8/site-packages/sqlalchemy/orm/query.py", line 2819, in first
    return self.limit(1)._iter().first()
  File "/usr/local/lib/python3.8/site-packages/sqlalchemy/orm/query.py", line 2903, in _iter
    result = self.session.execute(
  File "/usr/local/lib/python3.8/site-packages/sqlalchemy/orm/session.py", line 1692, in execute
    result = conn._execute_20(statement, params or {}, execution_options)
  File "/usr/local/lib/python3.8/site-packages/sqlalchemy/engine/base.py", line 1631, in _execute_20
    return meth(self, args_10style, kwargs_10style, execution_options)
  File "/usr/local/lib/python3.8/site-packages/sqlalchemy/sql/elements.py", line 326, in _execute_on_connection
    return connection._execute_clauseelement(
  File "/usr/local/lib/python3.8/site-packages/sqlalchemy/engine/base.py", line 1498, in _execute_clauseelement
    ret = self._execute_context(
  File "/usr/local/lib/python3.8/site-packages/sqlalchemy/engine/base.py", line 1862, in _execute_context
    self._handle_dbapi_exception(
  File "/usr/local/lib/python3.8/site-packages/sqlalchemy/engine/base.py", line 2043, in _handle_dbapi_exception
    util.raise_(
  File "/usr/local/lib/python3.8/site-packages/sqlalchemy/util/compat.py", line 207, in raise_
    raise exception
  File "/usr/local/lib/python3.8/site-packages/sqlalchemy/engine/base.py", line 1819, in _execute_context
    self.dialect.do_execute(
  File "/usr/local/lib/python3.8/site-packages/sqlalchemy/engine/default.py", line 732, in do_execute
    cursor.execute(statement, parameters)
sqlalchemy.exc.OperationalError: (sqlite3.OperationalError) no such table: users
[SQL: SELECT users.is_active AS users_is_active, users.id AS users_id, users.email AS users_email, users.password AS users_password, users.about AS users_about, users.authenticated AS users_authenticated, users.registered_on AS users_registered_on, users.is_admin AS users_is_admin 
FROM users 
WHERE users.email = ?
 LIMIT ? OFFSET ?]
[parameters: ('bob2@gmail.com', 1, 0)]
(Background on this error at: https://sqlalche.me/e/14/e3q8)
2022-04-28 15:13:21,138 [INFO] app: Browse page loading
2022-04-28 15:14:48,944 [ERROR] app: Exception on /songs/upload [POST]
Traceback (most recent call last):
  File "/usr/local/lib/python3.8/site-packages/flask/app.py", line 2077, in wsgi_app
    response = self.full_dispatch_request()
  File "/usr/local/lib/python3.8/site-packages/flask/app.py", line 1525, in full_dispatch_request
    rv = self.handle_user_exception(e)
  File "/usr/local/lib/python3.8/site-packages/flask/app.py", line 1523, in full_dispatch_request
    rv = self.dispatch_request()
  File "/usr/local/lib/python3.8/site-packages/flask/app.py", line 1509, in dispatch_request
    return self.ensure_sync(self.view_functions[rule.endpoint])(**req.view_args)
  File "/usr/local/lib/python3.8/site-packages/flask_login/utils.py", line 277, in decorated_view
    return current_app.ensure_sync(func)(*args, **kwargs)
  File "/home/myuser/app/songs/__init__.py", line 38, in songs_upload
    form.file.data.save(filepath)
  File "/usr/local/lib/python3.8/site-packages/werkzeug/datastructures.py", line 2996, in save
    dst = open(dst, "wb")
FileNotFoundError: [Errno 2] No such file or directory: './uploads/music.csv'
2022-04-28 15:16:40,366 [ERROR] app: Exception on /songs/upload [POST]
Traceback (most recent call last):
  File "/usr/local/lib/python3.8/site-packages/flask/app.py", line 2077, in wsgi_app
    response = self.full_dispatch_request()
  File "/usr/local/lib/python3.8/site-packages/flask/app.py", line 1525, in full_dispatch_request
    rv = self.handle_user_exception(e)
  File "/usr/local/lib/python3.8/site-packages/flask/app.py", line 1523, in full_dispatch_request
    rv = self.dispatch_request()
  File "/usr/local/lib/python3.8/site-packages/flask/app.py", line 1509, in dispatch_request
    return self.ensure_sync(self.view_functions[rule.endpoint])(**req.view_args)
  File "/usr/local/lib/python3.8/site-packages/flask_login/utils.py", line 277, in decorated_view
    return current_app.ensure_sync(func)(*args, **kwargs)
  File "/home/myuser/app/songs/__init__.py", line 38, in songs_upload
    form.file.data.save(filepath)
  File "/usr/local/lib/python3.8/site-packages/werkzeug/datastructures.py", line 2996, in save
    dst = open(dst, "wb")
FileNotFoundError: [Errno 2] No such file or directory: './uploads/music.csv'
